{
 "cells": [
  {
   "cell_type": "markdown",
   "metadata": {},
   "source": [
    "# toy problem 2"
   ]
  },
  {
   "cell_type": "markdown",
   "metadata": {},
   "source": [
    "## Generate data\n",
    "\n",
    "train_data size (100,500,128,128)\n",
    "\n",
    "validation size (10,500,128,128)\n",
    "\n",
    "test size (10,500,128,128)"
   ]
  },
  {
   "cell_type": "code",
   "execution_count": 2,
   "metadata": {},
   "outputs": [],
   "source": [
    "import os\n",
    "# import sys\n",
    "import numpy as np\n",
    "# import scipy as sp\n",
    "# from scipy import integrate\n",
    "from tqdm.notebook import tqdm\n",
    "import matplotlib.pyplot as plt\n",
    "import matplotlib.animation as animation\n",
    "# import torch\n",
    "\n",
    "# module_path = os.path.abspath(os.path.join('../src/'))\n",
    "# if module_path not in sys.path:\n",
    "#     sys.path.append(module_path)\n",
    "    \n",
    "    \n",
    "# import utils"
   ]
  },
  {
   "cell_type": "code",
   "execution_count": 51,
   "metadata": {},
   "outputs": [],
   "source": [
    "# def u(x,y):\n",
    "#     muu = 128/2\n",
    "#     sigma = 10\n",
    "#     return np.cosh((x+muu)/sigma)*np.cosh((y+muu)/sigma)\n",
    "#     dst = np.sqrt(x*x+y*y)\n",
    "#     gauss = np.exp(-( (dst-muu)**2 / ( 2.0 * sigma**2 ) ) )\n",
    "#     return gauss\n",
    "\n",
    "# define two modes\n",
    "def u(x, y, t):\n",
    "    muu = 128/2\n",
    "    sigma = 30\n",
    "    return 1./np.cosh((x-muu)/sigma)/np.cosh((y-muu)/sigma)*np.cos(w0*t)\n",
    "\n",
    "def v(x, y, t):\n",
    "    muu = 128/4\n",
    "    sigma = 5\n",
    "    return 1./np.cosh((x-muu)/sigma)/np.cosh((y-muu)/sigma)*np.cos(w1*t)\n",
    "\n",
    "# def v(x,y):\n",
    "#     muu = 128/4\n",
    "#     sigma = 5\n",
    "#     dst = np.sqrt(x*x+y*y)\n",
    "#     gauss = np.exp(-( (dst-muu)**2 / ( 2.0 * sigma**2 ) ) )\n",
    "#     return gauss\n",
    "\n",
    "def make_data(n_points, file_name, data_dir = './data/toy3a', n_time_steps = 500, dim = 128, num_periods_big = 8, w0=0.5, w1=1.0, width_small = 64):\n",
    "    \"\"\"\n",
    "    Makes data for toy2c\n",
    "    \n",
    "    Inputs:\n",
    "    n_points: int, how many data points \n",
    "    file_name: str, name of file to save\n",
    "    data_dir = './data/toy2': str, directory of where to store\n",
    "    n_time_steps = 500: int, how many time steps per data point\n",
    "    dim = 128: int, how many data points per dim, while be same in both x and y directions\n",
    "    num_periods_big = 8: int, how many periods of the slow scale\n",
    "    w0 = 0.5: float, frequency of slow scale\n",
    "    w1 = 1.0: float, frequency of fast scale\n",
    "    width_small = 8: width of small (fast) scale\n",
    "    \n",
    "    Output: \n",
    "    data: size (n_points,n_time_steps,dim, dim) will be returned and saved to file data_dir+file_name\n",
    "    \n",
    "    \"\"\"\n",
    "    print(width_small)\n",
    "    print(\"Making data\")\n",
    "    x = np.arange(dim)\n",
    "    y = np.arange(dim)\n",
    "    data = np.zeros((n_points, n_time_steps, dim, dim))\n",
    "\n",
    "    for i in tqdm(range(n_points)):\n",
    "        t_start = np.random.uniform(high=4*np.pi)\n",
    "        t = np.linspace(t_start, num_periods_big*4*np.pi + t_start, n_time_steps)\n",
    "\n",
    "\n",
    "        xgrid, ygrid, tgrid = np.meshgrid(x, y, t)\n",
    "        \n",
    "        Phi = u(xgrid, ygrid, tgrid) + v(xgrid, ygrid, tgrid)\n",
    "        \n",
    "\n",
    "#         Phi = np.cos(w0*tgrid)\n",
    "\n",
    "#         Phi[1:3, 0:2,:] = np.cos(w1*tgrid[1:3, 0:2,:]+np.pi/4)\n",
    "        scaled_Phi = (Phi.T - Phi.min()) / (Phi.max() - Phi.min())\n",
    "#         print(\"scaled_Phi shape = \", scaled_Phi.shape)\n",
    "#         plt.imshow(scaled_Phi[0])\n",
    "#         plt.colorbar()\n",
    "#         plt.show()\n",
    "#         hji\n",
    "        data[i] = scaled_Phi\n",
    "\n",
    "    print(\"making done, saving to \", os.path.join(data_dir, file_name))\n",
    "    np.save(os.path.join(data_dir, file_name), data)\n",
    "    print(\"done\")\n",
    "    \n",
    "    return data"
   ]
  },
  {
   "cell_type": "code",
   "execution_count": null,
   "metadata": {},
   "outputs": [
    {
     "name": "stdout",
     "output_type": "stream",
     "text": [
      "2\n",
      "Making data\n"
     ]
    },
    {
     "data": {
      "application/vnd.jupyter.widget-view+json": {
       "model_id": "0be0c42eb5594aea970cb7824cb90535",
       "version_major": 2,
       "version_minor": 0
      },
      "text/plain": [
       "  0%|          | 0/100 [00:00<?, ?it/s]"
      ]
     },
     "metadata": {},
     "output_type": "display_data"
    }
   ],
   "source": [
    "n_train_points = 100\n",
    "n_val_points = 10\n",
    "n_test_points = 10\n",
    "n_time_steps = 500\n",
    "dim = 128\n",
    "width_small = 2#int(dim/2)\n",
    "\n",
    "# params\n",
    "w0 = 0.5\n",
    "w1 = 1.0\n",
    "# width_small = 8\n",
    "num_periods_big = 8\n",
    "\n",
    "\n",
    "# paths\n",
    "data_dir = '../data/toy3a'\n",
    "result_dir = '../result/toy3a'\n",
    "\n",
    "\n",
    "x = np.arange(dim)\n",
    "y = np.arange(dim)\n",
    "train_data = make_data(n_train_points, 'train_data.npy', data_dir = data_dir,width_small=width_small,dim=dim) \n",
    "print(train_data.shape)\n",
    "plt.imshow(train_data[0,0])\n",
    "plt.colorbar()\n",
    "plt.show()\n",
    "val_data = make_data(n_val_points, 'val_data.npy', data_dir = data_dir,width_small=width_small,dim=dim) \n",
    "test_data = make_data(n_test_points, 'test_data.npy', data_dir=data_dir,width_small=width_small,dim=dim) \n",
    "\n"
   ]
  },
  {
   "cell_type": "code",
   "execution_count": null,
   "metadata": {},
   "outputs": [],
   "source": [
    "print(train_data.shape)\n",
    "plt.imshow(train_data[2,0])\n",
    "plt.colorbar()"
   ]
  },
  {
   "cell_type": "code",
   "execution_count": 9,
   "metadata": {},
   "outputs": [],
   "source": [
    "def animate(snapshots, normalize = True, file_name = \"animation.gif\"):\n",
    "    \"\"\"\n",
    "    Makes an animation of snapshots in time\n",
    "    \n",
    "    inputs:\n",
    "    snapshots: np.array of size (n_time_steps,1, dim, dim)\n",
    "    normalize = True: whether to fix axis between 0 and 1 or not\n",
    "    file_name = \"animation.gif\": file name of where to save gif\n",
    "    \n",
    "    outputs:\n",
    "    no returned output\n",
    "    gif saved to file_name\n",
    "    \"\"\"\n",
    "\n",
    "\n",
    "    fps = 30\n",
    "    nSeconds = len(snapshots)/fps\n",
    "    \n",
    "    # First set up the figure, the axis, and the plot element we want to animate\n",
    "    fig = plt.figure( figsize=(8,8) )\n",
    "\n",
    "    a = snapshots[0,:,:,:][0].T\n",
    "    if normalize:\n",
    "        im = plt.imshow(a, interpolation='none', aspect='auto', vmin=0.0, vmax=1.0)\n",
    "    else:\n",
    "        im = plt.imshow(a, interpolation='none', aspect='auto', vmin=np.min(snapshots), vmax=np.max(snapshots))\n",
    "    plt.colorbar()\n",
    "\n",
    "    print(\"Animating, may take a little while...\")\n",
    "\n",
    "    def animate_func(i):\n",
    "        if i % fps == 0:\n",
    "            print( '.', end ='' )\n",
    "\n",
    "        im.set_array(snapshots[i,:,:,:,][0].T)\n",
    "        return [im]\n",
    "\n",
    "    anim = animation.FuncAnimation(\n",
    "                                   fig,\n",
    "                                   animate_func,\n",
    "                                   frames = int(nSeconds * fps),\n",
    "                                   interval = 1000 / fps, # in ms\n",
    "                                   )\n",
    "    writergif = animation.PillowWriter(fps=30)\n",
    "    anim.save(file_name, writer=writergif)\n",
    "\n",
    "    print('Done! gif saved to ', file_name)\n"
   ]
  },
  {
   "cell_type": "code",
   "execution_count": null,
   "metadata": {},
   "outputs": [
    {
     "name": "stdout",
     "output_type": "stream",
     "text": [
      "Animating, may take a little while...\n",
      ".."
     ]
    },
    {
     "name": "stderr",
     "output_type": "stream",
     "text": [
      "ERROR:root:Internal Python error in the inspect module.\n",
      "Below is the traceback from this internal error.\n",
      "\n",
      "ERROR:root:Internal Python error in the inspect module.\n",
      "Below is the traceback from this internal error.\n",
      "\n"
     ]
    },
    {
     "name": "stdout",
     "output_type": "stream",
     "text": [
      "Traceback (most recent call last):\n",
      "  File \"C:\\Users\\16kat\\anaconda3\\lib\\site-packages\\matplotlib\\animation.py\", line 251, in saving\n",
      "    yield self\n",
      "  File \"C:\\Users\\16kat\\anaconda3\\lib\\site-packages\\matplotlib\\animation.py\", line 1141, in save\n",
      "    anim._draw_next_frame(d, blit=False)\n",
      "  File \"C:\\Users\\16kat\\anaconda3\\lib\\site-packages\\matplotlib\\animation.py\", line 1177, in _draw_next_frame\n",
      "    self._post_draw(framedata, blit)\n",
      "  File \"C:\\Users\\16kat\\anaconda3\\lib\\site-packages\\matplotlib\\animation.py\", line 1202, in _post_draw\n",
      "    self._fig.canvas.draw_idle()\n",
      "  File \"C:\\Users\\16kat\\anaconda3\\lib\\site-packages\\matplotlib\\backend_bases.py\", line 2012, in draw_idle\n",
      "    self.draw(*args, **kwargs)\n",
      "  File \"C:\\Users\\16kat\\anaconda3\\lib\\site-packages\\matplotlib\\backends\\backend_agg.py\", line 407, in draw\n",
      "    self.figure.draw(self.renderer)\n",
      "  File \"C:\\Users\\16kat\\anaconda3\\lib\\site-packages\\matplotlib\\artist.py\", line 41, in draw_wrapper\n",
      "    return draw(artist, renderer, *args, **kwargs)\n",
      "  File \"C:\\Users\\16kat\\anaconda3\\lib\\site-packages\\matplotlib\\figure.py\", line 1863, in draw\n",
      "    mimage._draw_list_compositing_images(\n",
      "  File \"C:\\Users\\16kat\\anaconda3\\lib\\site-packages\\matplotlib\\image.py\", line 131, in _draw_list_compositing_images\n",
      "    a.draw(renderer)\n",
      "  File \"C:\\Users\\16kat\\anaconda3\\lib\\site-packages\\matplotlib\\artist.py\", line 41, in draw_wrapper\n",
      "    return draw(artist, renderer, *args, **kwargs)\n",
      "  File \"C:\\Users\\16kat\\anaconda3\\lib\\site-packages\\matplotlib\\cbook\\deprecation.py\", line 411, in wrapper\n",
      "    return func(*inner_args, **inner_kwargs)\n",
      "  File \"C:\\Users\\16kat\\anaconda3\\lib\\site-packages\\matplotlib\\axes\\_base.py\", line 2747, in draw\n",
      "    mimage._draw_list_compositing_images(renderer, self, artists)\n",
      "  File \"C:\\Users\\16kat\\anaconda3\\lib\\site-packages\\matplotlib\\image.py\", line 131, in _draw_list_compositing_images\n",
      "    a.draw(renderer)\n",
      "  File \"C:\\Users\\16kat\\anaconda3\\lib\\site-packages\\matplotlib\\artist.py\", line 41, in draw_wrapper\n",
      "    return draw(artist, renderer, *args, **kwargs)\n",
      "  File \"C:\\Users\\16kat\\anaconda3\\lib\\site-packages\\matplotlib\\axis.py\", line 1169, in draw\n",
      "    tick.draw(renderer)\n",
      "  File \"C:\\Users\\16kat\\anaconda3\\lib\\site-packages\\matplotlib\\artist.py\", line 41, in draw_wrapper\n",
      "    return draw(artist, renderer, *args, **kwargs)\n",
      "  File \"C:\\Users\\16kat\\anaconda3\\lib\\site-packages\\matplotlib\\axis.py\", line 291, in draw\n",
      "    artist.draw(renderer)\n",
      "  File \"C:\\Users\\16kat\\anaconda3\\lib\\site-packages\\matplotlib\\artist.py\", line 41, in draw_wrapper\n",
      "    return draw(artist, renderer, *args, **kwargs)\n",
      "  File \"C:\\Users\\16kat\\anaconda3\\lib\\site-packages\\matplotlib\\text.py\", line 725, in draw\n",
      "    textrenderer.draw_text(gc, x, y, clean_line,\n",
      "  File \"C:\\Users\\16kat\\anaconda3\\lib\\site-packages\\matplotlib\\backends\\backend_agg.py\", line 195, in draw_text\n",
      "    font = self._get_agg_font(prop)\n",
      "  File \"C:\\Users\\16kat\\anaconda3\\lib\\site-packages\\matplotlib\\backends\\backend_agg.py\", line 272, in _get_agg_font\n",
      "    fname = findfont(prop)\n",
      "  File \"C:\\Users\\16kat\\anaconda3\\lib\\site-packages\\matplotlib\\font_manager.py\", line 1314, in findfont\n",
      "    return os.path.realpath(filename)\n",
      "  File \"C:\\Users\\16kat\\anaconda3\\lib\\ntpath.py\", line 647, in realpath\n",
      "    path = _getfinalpathname(path)\n",
      "KeyboardInterrupt\n",
      "\n",
      "During handling of the above exception, another exception occurred:\n",
      "\n",
      "Traceback (most recent call last):\n",
      "  File \"C:\\Users\\16kat\\anaconda3\\lib\\site-packages\\IPython\\core\\interactiveshell.py\", line 3418, in run_code\n",
      "    exec(code_obj, self.user_global_ns, self.user_ns)\n",
      "  File \"<ipython-input-6-4e619ad7cffb>\", line 1, in <module>\n",
      "    animate(train_data[0].reshape(n_time_steps,1, dim, dim), file_name = os.path.join(result_dir,'train_data.gif'))\n",
      "  File \"<ipython-input-5-2e1703cf0959>\", line 45, in animate\n",
      "    anim.save(file_name, writer=writergif)\n",
      "  File \"C:\\Users\\16kat\\anaconda3\\lib\\site-packages\\matplotlib\\animation.py\", line 1145, in save\n",
      "    writer.grab_frame(**savefig_kwargs)\n",
      "  File \"C:\\Users\\16kat\\anaconda3\\lib\\contextlib.py\", line 131, in __exit__\n",
      "    self.gen.throw(type, value, traceback)\n",
      "  File \"C:\\Users\\16kat\\anaconda3\\lib\\site-packages\\matplotlib\\animation.py\", line 253, in saving\n",
      "    self.finish()\n",
      "  File \"C:\\Users\\16kat\\anaconda3\\lib\\site-packages\\matplotlib\\animation.py\", line 554, in finish\n",
      "    self._frames[0].save(\n",
      "  File \"C:\\Users\\16kat\\anaconda3\\lib\\site-packages\\PIL\\Image.py\", line 2148, in save\n",
      "    fp = builtins.open(filename, \"w+b\")\n",
      "FileNotFoundError: [Errno 2] No such file or directory: './result/toy2a\\\\train_data.gif'\n",
      "\n",
      "During handling of the above exception, another exception occurred:\n",
      "\n",
      "Traceback (most recent call last):\n",
      "  File \"C:\\Users\\16kat\\anaconda3\\lib\\site-packages\\IPython\\core\\interactiveshell.py\", line 2045, in showtraceback\n",
      "    stb = value._render_traceback_()\n",
      "AttributeError: 'FileNotFoundError' object has no attribute '_render_traceback_'\n",
      "\n",
      "During handling of the above exception, another exception occurred:\n",
      "\n",
      "Traceback (most recent call last):\n",
      "  File \"C:\\Users\\16kat\\anaconda3\\lib\\site-packages\\IPython\\core\\ultratb.py\", line 1170, in get_records\n",
      "    return _fixed_getinnerframes(etb, number_of_lines_of_context, tb_offset)\n",
      "  File \"C:\\Users\\16kat\\anaconda3\\lib\\site-packages\\IPython\\core\\ultratb.py\", line 316, in wrapped\n",
      "    return f(*args, **kwargs)\n",
      "  File \"C:\\Users\\16kat\\anaconda3\\lib\\site-packages\\IPython\\core\\ultratb.py\", line 350, in _fixed_getinnerframes\n",
      "    records = fix_frame_records_filenames(inspect.getinnerframes(etb, context))\n",
      "  File \"C:\\Users\\16kat\\anaconda3\\lib\\inspect.py\", line 1503, in getinnerframes\n",
      "    frameinfo = (tb.tb_frame,) + getframeinfo(tb, context)\n",
      "  File \"C:\\Users\\16kat\\anaconda3\\lib\\inspect.py\", line 1461, in getframeinfo\n",
      "    filename = getsourcefile(frame) or getfile(frame)\n",
      "  File \"C:\\Users\\16kat\\anaconda3\\lib\\inspect.py\", line 708, in getsourcefile\n",
      "    if getattr(getmodule(object, filename), '__loader__', None) is not None:\n",
      "  File \"C:\\Users\\16kat\\anaconda3\\lib\\inspect.py\", line 751, in getmodule\n",
      "    f = getabsfile(module)\n",
      "  File \"C:\\Users\\16kat\\anaconda3\\lib\\inspect.py\", line 720, in getabsfile\n",
      "    _filename = getsourcefile(object) or getfile(object)\n",
      "  File \"C:\\Users\\16kat\\anaconda3\\lib\\inspect.py\", line 705, in getsourcefile\n",
      "    if os.path.exists(filename):\n",
      "  File \"C:\\Users\\16kat\\anaconda3\\lib\\genericpath.py\", line 19, in exists\n",
      "    os.stat(path)\n",
      "KeyboardInterrupt\n",
      "Traceback (most recent call last):\n",
      "  File \"C:\\Users\\16kat\\anaconda3\\lib\\site-packages\\matplotlib\\animation.py\", line 251, in saving\n",
      "    yield self\n",
      "  File \"C:\\Users\\16kat\\anaconda3\\lib\\site-packages\\matplotlib\\animation.py\", line 1141, in save\n",
      "    anim._draw_next_frame(d, blit=False)\n",
      "  File \"C:\\Users\\16kat\\anaconda3\\lib\\site-packages\\matplotlib\\animation.py\", line 1177, in _draw_next_frame\n",
      "    self._post_draw(framedata, blit)\n",
      "  File \"C:\\Users\\16kat\\anaconda3\\lib\\site-packages\\matplotlib\\animation.py\", line 1202, in _post_draw\n",
      "    self._fig.canvas.draw_idle()\n",
      "  File \"C:\\Users\\16kat\\anaconda3\\lib\\site-packages\\matplotlib\\backend_bases.py\", line 2012, in draw_idle\n",
      "    self.draw(*args, **kwargs)\n",
      "  File \"C:\\Users\\16kat\\anaconda3\\lib\\site-packages\\matplotlib\\backends\\backend_agg.py\", line 407, in draw\n",
      "    self.figure.draw(self.renderer)\n",
      "  File \"C:\\Users\\16kat\\anaconda3\\lib\\site-packages\\matplotlib\\artist.py\", line 41, in draw_wrapper\n",
      "    return draw(artist, renderer, *args, **kwargs)\n",
      "  File \"C:\\Users\\16kat\\anaconda3\\lib\\site-packages\\matplotlib\\figure.py\", line 1863, in draw\n",
      "    mimage._draw_list_compositing_images(\n",
      "  File \"C:\\Users\\16kat\\anaconda3\\lib\\site-packages\\matplotlib\\image.py\", line 131, in _draw_list_compositing_images\n",
      "    a.draw(renderer)\n",
      "  File \"C:\\Users\\16kat\\anaconda3\\lib\\site-packages\\matplotlib\\artist.py\", line 41, in draw_wrapper\n",
      "    return draw(artist, renderer, *args, **kwargs)\n",
      "  File \"C:\\Users\\16kat\\anaconda3\\lib\\site-packages\\matplotlib\\cbook\\deprecation.py\", line 411, in wrapper\n",
      "    return func(*inner_args, **inner_kwargs)\n",
      "  File \"C:\\Users\\16kat\\anaconda3\\lib\\site-packages\\matplotlib\\axes\\_base.py\", line 2747, in draw\n",
      "    mimage._draw_list_compositing_images(renderer, self, artists)\n",
      "  File \"C:\\Users\\16kat\\anaconda3\\lib\\site-packages\\matplotlib\\image.py\", line 131, in _draw_list_compositing_images\n",
      "    a.draw(renderer)\n",
      "  File \"C:\\Users\\16kat\\anaconda3\\lib\\site-packages\\matplotlib\\artist.py\", line 41, in draw_wrapper\n",
      "    return draw(artist, renderer, *args, **kwargs)\n",
      "  File \"C:\\Users\\16kat\\anaconda3\\lib\\site-packages\\matplotlib\\axis.py\", line 1169, in draw\n",
      "    tick.draw(renderer)\n",
      "  File \"C:\\Users\\16kat\\anaconda3\\lib\\site-packages\\matplotlib\\artist.py\", line 41, in draw_wrapper\n",
      "    return draw(artist, renderer, *args, **kwargs)\n",
      "  File \"C:\\Users\\16kat\\anaconda3\\lib\\site-packages\\matplotlib\\axis.py\", line 291, in draw\n",
      "    artist.draw(renderer)\n",
      "  File \"C:\\Users\\16kat\\anaconda3\\lib\\site-packages\\matplotlib\\artist.py\", line 41, in draw_wrapper\n",
      "    return draw(artist, renderer, *args, **kwargs)\n",
      "  File \"C:\\Users\\16kat\\anaconda3\\lib\\site-packages\\matplotlib\\text.py\", line 725, in draw\n",
      "    textrenderer.draw_text(gc, x, y, clean_line,\n",
      "  File \"C:\\Users\\16kat\\anaconda3\\lib\\site-packages\\matplotlib\\backends\\backend_agg.py\", line 195, in draw_text\n",
      "    font = self._get_agg_font(prop)\n",
      "  File \"C:\\Users\\16kat\\anaconda3\\lib\\site-packages\\matplotlib\\backends\\backend_agg.py\", line 272, in _get_agg_font\n",
      "    fname = findfont(prop)\n",
      "  File \"C:\\Users\\16kat\\anaconda3\\lib\\site-packages\\matplotlib\\font_manager.py\", line 1314, in findfont\n",
      "    return os.path.realpath(filename)\n",
      "  File \"C:\\Users\\16kat\\anaconda3\\lib\\ntpath.py\", line 647, in realpath\n",
      "    path = _getfinalpathname(path)\n",
      "KeyboardInterrupt\n",
      "\n",
      "During handling of the above exception, another exception occurred:\n",
      "\n",
      "Traceback (most recent call last):\n",
      "  File \"C:\\Users\\16kat\\anaconda3\\lib\\site-packages\\IPython\\core\\interactiveshell.py\", line 3418, in run_code\n",
      "    exec(code_obj, self.user_global_ns, self.user_ns)\n",
      "  File \"<ipython-input-6-4e619ad7cffb>\", line 1, in <module>\n",
      "    animate(train_data[0].reshape(n_time_steps,1, dim, dim), file_name = os.path.join(result_dir,'train_data.gif'))\n",
      "  File \"<ipython-input-5-2e1703cf0959>\", line 45, in animate\n",
      "    anim.save(file_name, writer=writergif)\n",
      "  File \"C:\\Users\\16kat\\anaconda3\\lib\\site-packages\\matplotlib\\animation.py\", line 1145, in save\n",
      "    writer.grab_frame(**savefig_kwargs)\n",
      "  File \"C:\\Users\\16kat\\anaconda3\\lib\\contextlib.py\", line 131, in __exit__\n",
      "    self.gen.throw(type, value, traceback)\n",
      "  File \"C:\\Users\\16kat\\anaconda3\\lib\\site-packages\\matplotlib\\animation.py\", line 253, in saving\n",
      "    self.finish()\n",
      "  File \"C:\\Users\\16kat\\anaconda3\\lib\\site-packages\\matplotlib\\animation.py\", line 554, in finish\n",
      "    self._frames[0].save(\n",
      "  File \"C:\\Users\\16kat\\anaconda3\\lib\\site-packages\\PIL\\Image.py\", line 2148, in save\n",
      "    fp = builtins.open(filename, \"w+b\")\n",
      "FileNotFoundError: [Errno 2] No such file or directory: './result/toy2a\\\\train_data.gif'\n",
      "\n",
      "During handling of the above exception, another exception occurred:\n",
      "\n",
      "Traceback (most recent call last):\n",
      "  File \"C:\\Users\\16kat\\anaconda3\\lib\\site-packages\\IPython\\core\\interactiveshell.py\", line 2045, in showtraceback\n",
      "    stb = value._render_traceback_()\n",
      "AttributeError: 'FileNotFoundError' object has no attribute '_render_traceback_'\n",
      "\n",
      "During handling of the above exception, another exception occurred:\n",
      "\n",
      "Traceback (most recent call last):\n",
      "  File \"C:\\Users\\16kat\\anaconda3\\lib\\site-packages\\IPython\\core\\interactiveshell.py\", line 3338, in run_ast_nodes\n",
      "    if (await self.run_code(code, result,  async_=asy)):\n",
      "  File \"C:\\Users\\16kat\\anaconda3\\lib\\site-packages\\IPython\\core\\interactiveshell.py\", line 3435, in run_code\n",
      "    self.showtraceback(running_compiled_code=True)\n",
      "  File \"C:\\Users\\16kat\\anaconda3\\lib\\site-packages\\IPython\\core\\interactiveshell.py\", line 2047, in showtraceback\n",
      "    stb = self.InteractiveTB.structured_traceback(etype,\n",
      "  File \"C:\\Users\\16kat\\anaconda3\\lib\\site-packages\\IPython\\core\\ultratb.py\", line 1436, in structured_traceback\n",
      "    return FormattedTB.structured_traceback(\n",
      "  File \"C:\\Users\\16kat\\anaconda3\\lib\\site-packages\\IPython\\core\\ultratb.py\", line 1336, in structured_traceback\n",
      "    return VerboseTB.structured_traceback(\n",
      "  File \"C:\\Users\\16kat\\anaconda3\\lib\\site-packages\\IPython\\core\\ultratb.py\", line 1193, in structured_traceback\n",
      "    formatted_exception = self.format_exception_as_a_whole(etype, evalue, etb, number_of_lines_of_context,\n",
      "  File \"C:\\Users\\16kat\\anaconda3\\lib\\site-packages\\IPython\\core\\ultratb.py\", line 1151, in format_exception_as_a_whole\n",
      "    last_unique, recursion_repeat = find_recursion(orig_etype, evalue, records)\n",
      "  File \"C:\\Users\\16kat\\anaconda3\\lib\\site-packages\\IPython\\core\\ultratb.py\", line 451, in find_recursion\n",
      "    return len(records), 0\n",
      "TypeError: object of type 'NoneType' has no len()\n",
      "\n",
      "During handling of the above exception, another exception occurred:\n",
      "\n",
      "Traceback (most recent call last):\n",
      "  File \"C:\\Users\\16kat\\anaconda3\\lib\\site-packages\\IPython\\core\\interactiveshell.py\", line 2045, in showtraceback\n",
      "    stb = value._render_traceback_()\n",
      "AttributeError: 'TypeError' object has no attribute '_render_traceback_'\n",
      "\n",
      "During handling of the above exception, another exception occurred:\n",
      "\n",
      "Traceback (most recent call last):\n",
      "  File \"C:\\Users\\16kat\\anaconda3\\lib\\site-packages\\IPython\\core\\ultratb.py\", line 1170, in get_records\n",
      "    return _fixed_getinnerframes(etb, number_of_lines_of_context, tb_offset)\n",
      "  File \"C:\\Users\\16kat\\anaconda3\\lib\\site-packages\\IPython\\core\\ultratb.py\", line 316, in wrapped\n",
      "    return f(*args, **kwargs)\n",
      "  File \"C:\\Users\\16kat\\anaconda3\\lib\\site-packages\\IPython\\core\\ultratb.py\", line 350, in _fixed_getinnerframes\n",
      "    records = fix_frame_records_filenames(inspect.getinnerframes(etb, context))\n",
      "  File \"C:\\Users\\16kat\\anaconda3\\lib\\inspect.py\", line 1503, in getinnerframes\n",
      "    frameinfo = (tb.tb_frame,) + getframeinfo(tb, context)\n",
      "  File \"C:\\Users\\16kat\\anaconda3\\lib\\inspect.py\", line 1461, in getframeinfo\n",
      "    filename = getsourcefile(frame) or getfile(frame)\n",
      "  File \"C:\\Users\\16kat\\anaconda3\\lib\\inspect.py\", line 708, in getsourcefile\n",
      "    if getattr(getmodule(object, filename), '__loader__', None) is not None:\n",
      "  File \"C:\\Users\\16kat\\anaconda3\\lib\\inspect.py\", line 754, in getmodule\n",
      "    os.path.realpath(f)] = module.__name__\n",
      "  File \"C:\\Users\\16kat\\anaconda3\\lib\\ntpath.py\", line 647, in realpath\n",
      "    path = _getfinalpathname(path)\n",
      "KeyboardInterrupt\n"
     ]
    },
    {
     "name": "stderr",
     "output_type": "stream",
     "text": [
      "ERROR:root:Internal Python error in the inspect module.\n",
      "Below is the traceback from this internal error.\n",
      "\n"
     ]
    },
    {
     "name": "stdout",
     "output_type": "stream",
     "text": [
      "Traceback (most recent call last):\n",
      "  File \"C:\\Users\\16kat\\anaconda3\\lib\\site-packages\\matplotlib\\animation.py\", line 251, in saving\n",
      "    yield self\n",
      "  File \"C:\\Users\\16kat\\anaconda3\\lib\\site-packages\\matplotlib\\animation.py\", line 1141, in save\n",
      "    anim._draw_next_frame(d, blit=False)\n",
      "  File \"C:\\Users\\16kat\\anaconda3\\lib\\site-packages\\matplotlib\\animation.py\", line 1177, in _draw_next_frame\n",
      "    self._post_draw(framedata, blit)\n",
      "  File \"C:\\Users\\16kat\\anaconda3\\lib\\site-packages\\matplotlib\\animation.py\", line 1202, in _post_draw\n",
      "    self._fig.canvas.draw_idle()\n",
      "  File \"C:\\Users\\16kat\\anaconda3\\lib\\site-packages\\matplotlib\\backend_bases.py\", line 2012, in draw_idle\n",
      "    self.draw(*args, **kwargs)\n",
      "  File \"C:\\Users\\16kat\\anaconda3\\lib\\site-packages\\matplotlib\\backends\\backend_agg.py\", line 407, in draw\n",
      "    self.figure.draw(self.renderer)\n",
      "  File \"C:\\Users\\16kat\\anaconda3\\lib\\site-packages\\matplotlib\\artist.py\", line 41, in draw_wrapper\n",
      "    return draw(artist, renderer, *args, **kwargs)\n",
      "  File \"C:\\Users\\16kat\\anaconda3\\lib\\site-packages\\matplotlib\\figure.py\", line 1863, in draw\n",
      "    mimage._draw_list_compositing_images(\n",
      "  File \"C:\\Users\\16kat\\anaconda3\\lib\\site-packages\\matplotlib\\image.py\", line 131, in _draw_list_compositing_images\n",
      "    a.draw(renderer)\n",
      "  File \"C:\\Users\\16kat\\anaconda3\\lib\\site-packages\\matplotlib\\artist.py\", line 41, in draw_wrapper\n",
      "    return draw(artist, renderer, *args, **kwargs)\n",
      "  File \"C:\\Users\\16kat\\anaconda3\\lib\\site-packages\\matplotlib\\cbook\\deprecation.py\", line 411, in wrapper\n",
      "    return func(*inner_args, **inner_kwargs)\n",
      "  File \"C:\\Users\\16kat\\anaconda3\\lib\\site-packages\\matplotlib\\axes\\_base.py\", line 2747, in draw\n",
      "    mimage._draw_list_compositing_images(renderer, self, artists)\n",
      "  File \"C:\\Users\\16kat\\anaconda3\\lib\\site-packages\\matplotlib\\image.py\", line 131, in _draw_list_compositing_images\n",
      "    a.draw(renderer)\n",
      "  File \"C:\\Users\\16kat\\anaconda3\\lib\\site-packages\\matplotlib\\artist.py\", line 41, in draw_wrapper\n",
      "    return draw(artist, renderer, *args, **kwargs)\n",
      "  File \"C:\\Users\\16kat\\anaconda3\\lib\\site-packages\\matplotlib\\axis.py\", line 1169, in draw\n",
      "    tick.draw(renderer)\n",
      "  File \"C:\\Users\\16kat\\anaconda3\\lib\\site-packages\\matplotlib\\artist.py\", line 41, in draw_wrapper\n",
      "    return draw(artist, renderer, *args, **kwargs)\n",
      "  File \"C:\\Users\\16kat\\anaconda3\\lib\\site-packages\\matplotlib\\axis.py\", line 291, in draw\n",
      "    artist.draw(renderer)\n",
      "  File \"C:\\Users\\16kat\\anaconda3\\lib\\site-packages\\matplotlib\\artist.py\", line 41, in draw_wrapper\n",
      "    return draw(artist, renderer, *args, **kwargs)\n",
      "  File \"C:\\Users\\16kat\\anaconda3\\lib\\site-packages\\matplotlib\\text.py\", line 725, in draw\n",
      "    textrenderer.draw_text(gc, x, y, clean_line,\n",
      "  File \"C:\\Users\\16kat\\anaconda3\\lib\\site-packages\\matplotlib\\backends\\backend_agg.py\", line 195, in draw_text\n",
      "    font = self._get_agg_font(prop)\n",
      "  File \"C:\\Users\\16kat\\anaconda3\\lib\\site-packages\\matplotlib\\backends\\backend_agg.py\", line 272, in _get_agg_font\n",
      "    fname = findfont(prop)\n",
      "  File \"C:\\Users\\16kat\\anaconda3\\lib\\site-packages\\matplotlib\\font_manager.py\", line 1314, in findfont\n",
      "    return os.path.realpath(filename)\n",
      "  File \"C:\\Users\\16kat\\anaconda3\\lib\\ntpath.py\", line 647, in realpath\n",
      "    path = _getfinalpathname(path)\n",
      "KeyboardInterrupt\n",
      "\n",
      "During handling of the above exception, another exception occurred:\n",
      "\n",
      "Traceback (most recent call last):\n",
      "  File \"C:\\Users\\16kat\\anaconda3\\lib\\site-packages\\IPython\\core\\interactiveshell.py\", line 3418, in run_code\n",
      "    exec(code_obj, self.user_global_ns, self.user_ns)\n",
      "  File \"<ipython-input-6-4e619ad7cffb>\", line 1, in <module>\n",
      "    animate(train_data[0].reshape(n_time_steps,1, dim, dim), file_name = os.path.join(result_dir,'train_data.gif'))\n",
      "  File \"<ipython-input-5-2e1703cf0959>\", line 45, in animate\n",
      "    anim.save(file_name, writer=writergif)\n",
      "  File \"C:\\Users\\16kat\\anaconda3\\lib\\site-packages\\matplotlib\\animation.py\", line 1145, in save\n",
      "    writer.grab_frame(**savefig_kwargs)\n",
      "  File \"C:\\Users\\16kat\\anaconda3\\lib\\contextlib.py\", line 131, in __exit__\n",
      "    self.gen.throw(type, value, traceback)\n",
      "  File \"C:\\Users\\16kat\\anaconda3\\lib\\site-packages\\matplotlib\\animation.py\", line 253, in saving\n",
      "    self.finish()\n",
      "  File \"C:\\Users\\16kat\\anaconda3\\lib\\site-packages\\matplotlib\\animation.py\", line 554, in finish\n",
      "    self._frames[0].save(\n",
      "  File \"C:\\Users\\16kat\\anaconda3\\lib\\site-packages\\PIL\\Image.py\", line 2148, in save\n",
      "    fp = builtins.open(filename, \"w+b\")\n",
      "FileNotFoundError: [Errno 2] No such file or directory: './result/toy2a\\\\train_data.gif'\n",
      "\n",
      "During handling of the above exception, another exception occurred:\n",
      "\n",
      "Traceback (most recent call last):\n",
      "  File \"C:\\Users\\16kat\\anaconda3\\lib\\site-packages\\IPython\\core\\interactiveshell.py\", line 2045, in showtraceback\n",
      "    stb = value._render_traceback_()\n",
      "AttributeError: 'FileNotFoundError' object has no attribute '_render_traceback_'\n",
      "\n",
      "During handling of the above exception, another exception occurred:\n",
      "\n",
      "Traceback (most recent call last):\n",
      "  File \"C:\\Users\\16kat\\anaconda3\\lib\\site-packages\\IPython\\core\\interactiveshell.py\", line 3338, in run_ast_nodes\n",
      "    if (await self.run_code(code, result,  async_=asy)):\n",
      "  File \"C:\\Users\\16kat\\anaconda3\\lib\\site-packages\\IPython\\core\\interactiveshell.py\", line 3435, in run_code\n",
      "    self.showtraceback(running_compiled_code=True)\n",
      "  File \"C:\\Users\\16kat\\anaconda3\\lib\\site-packages\\IPython\\core\\interactiveshell.py\", line 2047, in showtraceback\n",
      "    stb = self.InteractiveTB.structured_traceback(etype,\n",
      "  File \"C:\\Users\\16kat\\anaconda3\\lib\\site-packages\\IPython\\core\\ultratb.py\", line 1436, in structured_traceback\n",
      "    return FormattedTB.structured_traceback(\n",
      "  File \"C:\\Users\\16kat\\anaconda3\\lib\\site-packages\\IPython\\core\\ultratb.py\", line 1336, in structured_traceback\n",
      "    return VerboseTB.structured_traceback(\n",
      "  File \"C:\\Users\\16kat\\anaconda3\\lib\\site-packages\\IPython\\core\\ultratb.py\", line 1193, in structured_traceback\n",
      "    formatted_exception = self.format_exception_as_a_whole(etype, evalue, etb, number_of_lines_of_context,\n",
      "  File \"C:\\Users\\16kat\\anaconda3\\lib\\site-packages\\IPython\\core\\ultratb.py\", line 1151, in format_exception_as_a_whole\n",
      "    last_unique, recursion_repeat = find_recursion(orig_etype, evalue, records)\n",
      "  File \"C:\\Users\\16kat\\anaconda3\\lib\\site-packages\\IPython\\core\\ultratb.py\", line 451, in find_recursion\n",
      "    return len(records), 0\n",
      "TypeError: object of type 'NoneType' has no len()\n",
      "\n",
      "During handling of the above exception, another exception occurred:\n",
      "\n",
      "Traceback (most recent call last):\n",
      "  File \"C:\\Users\\16kat\\anaconda3\\lib\\site-packages\\IPython\\core\\interactiveshell.py\", line 2045, in showtraceback\n",
      "    stb = value._render_traceback_()\n",
      "AttributeError: 'TypeError' object has no attribute '_render_traceback_'\n",
      "\n",
      "During handling of the above exception, another exception occurred:\n",
      "\n",
      "Traceback (most recent call last):\n",
      "  File \"C:\\Users\\16kat\\anaconda3\\lib\\site-packages\\IPython\\core\\interactiveshell.py\", line 2923, in _run_cell\n",
      "    return runner(coro)\n",
      "  File \"C:\\Users\\16kat\\anaconda3\\lib\\site-packages\\IPython\\core\\async_helpers.py\", line 68, in _pseudo_sync_runner\n",
      "    coro.send(None)\n",
      "  File \"C:\\Users\\16kat\\anaconda3\\lib\\site-packages\\IPython\\core\\interactiveshell.py\", line 3146, in run_cell_async\n",
      "    has_raised = await self.run_ast_nodes(code_ast.body, cell_name,\n",
      "  File \"C:\\Users\\16kat\\anaconda3\\lib\\site-packages\\IPython\\core\\interactiveshell.py\", line 3357, in run_ast_nodes\n",
      "    self.showtraceback()\n",
      "  File \"C:\\Users\\16kat\\anaconda3\\lib\\site-packages\\IPython\\core\\interactiveshell.py\", line 2047, in showtraceback\n",
      "    stb = self.InteractiveTB.structured_traceback(etype,\n",
      "  File \"C:\\Users\\16kat\\anaconda3\\lib\\site-packages\\IPython\\core\\ultratb.py\", line 1436, in structured_traceback\n",
      "    return FormattedTB.structured_traceback(\n",
      "  File \"C:\\Users\\16kat\\anaconda3\\lib\\site-packages\\IPython\\core\\ultratb.py\", line 1336, in structured_traceback\n",
      "    return VerboseTB.structured_traceback(\n",
      "  File \"C:\\Users\\16kat\\anaconda3\\lib\\site-packages\\IPython\\core\\ultratb.py\", line 1211, in structured_traceback\n",
      "    formatted_exceptions += self.format_exception_as_a_whole(etype, evalue, etb, lines_of_context,\n",
      "  File \"C:\\Users\\16kat\\anaconda3\\lib\\site-packages\\IPython\\core\\ultratb.py\", line 1151, in format_exception_as_a_whole\n",
      "    last_unique, recursion_repeat = find_recursion(orig_etype, evalue, records)\n",
      "  File \"C:\\Users\\16kat\\anaconda3\\lib\\site-packages\\IPython\\core\\ultratb.py\", line 451, in find_recursion\n",
      "    return len(records), 0\n",
      "TypeError: object of type 'NoneType' has no len()\n",
      "\n",
      "During handling of the above exception, another exception occurred:\n",
      "\n",
      "Traceback (most recent call last):\n",
      "  File \"C:\\Users\\16kat\\anaconda3\\lib\\site-packages\\IPython\\core\\interactiveshell.py\", line 2045, in showtraceback\n",
      "    stb = value._render_traceback_()\n",
      "AttributeError: 'TypeError' object has no attribute '_render_traceback_'\n",
      "\n",
      "During handling of the above exception, another exception occurred:\n",
      "\n",
      "Traceback (most recent call last):\n",
      "  File \"C:\\Users\\16kat\\anaconda3\\lib\\site-packages\\IPython\\core\\ultratb.py\", line 1170, in get_records\n",
      "    return _fixed_getinnerframes(etb, number_of_lines_of_context, tb_offset)\n",
      "  File \"C:\\Users\\16kat\\anaconda3\\lib\\site-packages\\IPython\\core\\ultratb.py\", line 316, in wrapped\n",
      "    return f(*args, **kwargs)\n",
      "  File \"C:\\Users\\16kat\\anaconda3\\lib\\site-packages\\IPython\\core\\ultratb.py\", line 350, in _fixed_getinnerframes\n",
      "    records = fix_frame_records_filenames(inspect.getinnerframes(etb, context))\n",
      "  File \"C:\\Users\\16kat\\anaconda3\\lib\\inspect.py\", line 1503, in getinnerframes\n",
      "    frameinfo = (tb.tb_frame,) + getframeinfo(tb, context)\n",
      "  File \"C:\\Users\\16kat\\anaconda3\\lib\\inspect.py\", line 1461, in getframeinfo\n",
      "    filename = getsourcefile(frame) or getfile(frame)\n",
      "  File \"C:\\Users\\16kat\\anaconda3\\lib\\inspect.py\", line 708, in getsourcefile\n",
      "    if getattr(getmodule(object, filename), '__loader__', None) is not None:\n",
      "  File \"C:\\Users\\16kat\\anaconda3\\lib\\inspect.py\", line 751, in getmodule\n",
      "    f = getabsfile(module)\n",
      "  File \"C:\\Users\\16kat\\anaconda3\\lib\\inspect.py\", line 720, in getabsfile\n",
      "    _filename = getsourcefile(object) or getfile(object)\n",
      "  File \"C:\\Users\\16kat\\anaconda3\\lib\\inspect.py\", line 705, in getsourcefile\n",
      "    if os.path.exists(filename):\n",
      "  File \"C:\\Users\\16kat\\anaconda3\\lib\\genericpath.py\", line 19, in exists\n",
      "    os.stat(path)\n",
      "KeyboardInterrupt\n",
      "Error in callback <function flush_figures at 0x000001E2C30F44C0> (for post_execute):\n"
     ]
    },
    {
     "name": "stderr",
     "output_type": "stream",
     "text": [
      "ERROR:root:Internal Python error in the inspect module.\n",
      "Below is the traceback from this internal error.\n",
      "\n"
     ]
    },
    {
     "name": "stdout",
     "output_type": "stream",
     "text": [
      "Traceback (most recent call last):\n",
      "  File \"C:\\Users\\16kat\\anaconda3\\lib\\site-packages\\matplotlib\\animation.py\", line 251, in saving\n",
      "    yield self\n",
      "  File \"C:\\Users\\16kat\\anaconda3\\lib\\site-packages\\matplotlib\\animation.py\", line 1141, in save\n",
      "    anim._draw_next_frame(d, blit=False)\n",
      "  File \"C:\\Users\\16kat\\anaconda3\\lib\\site-packages\\matplotlib\\animation.py\", line 1177, in _draw_next_frame\n",
      "    self._post_draw(framedata, blit)\n",
      "  File \"C:\\Users\\16kat\\anaconda3\\lib\\site-packages\\matplotlib\\animation.py\", line 1202, in _post_draw\n",
      "    self._fig.canvas.draw_idle()\n",
      "  File \"C:\\Users\\16kat\\anaconda3\\lib\\site-packages\\matplotlib\\backend_bases.py\", line 2012, in draw_idle\n",
      "    self.draw(*args, **kwargs)\n",
      "  File \"C:\\Users\\16kat\\anaconda3\\lib\\site-packages\\matplotlib\\backends\\backend_agg.py\", line 407, in draw\n",
      "    self.figure.draw(self.renderer)\n",
      "  File \"C:\\Users\\16kat\\anaconda3\\lib\\site-packages\\matplotlib\\artist.py\", line 41, in draw_wrapper\n",
      "    return draw(artist, renderer, *args, **kwargs)\n",
      "  File \"C:\\Users\\16kat\\anaconda3\\lib\\site-packages\\matplotlib\\figure.py\", line 1863, in draw\n",
      "    mimage._draw_list_compositing_images(\n",
      "  File \"C:\\Users\\16kat\\anaconda3\\lib\\site-packages\\matplotlib\\image.py\", line 131, in _draw_list_compositing_images\n",
      "    a.draw(renderer)\n",
      "  File \"C:\\Users\\16kat\\anaconda3\\lib\\site-packages\\matplotlib\\artist.py\", line 41, in draw_wrapper\n",
      "    return draw(artist, renderer, *args, **kwargs)\n",
      "  File \"C:\\Users\\16kat\\anaconda3\\lib\\site-packages\\matplotlib\\cbook\\deprecation.py\", line 411, in wrapper\n",
      "    return func(*inner_args, **inner_kwargs)\n",
      "  File \"C:\\Users\\16kat\\anaconda3\\lib\\site-packages\\matplotlib\\axes\\_base.py\", line 2747, in draw\n",
      "    mimage._draw_list_compositing_images(renderer, self, artists)\n",
      "  File \"C:\\Users\\16kat\\anaconda3\\lib\\site-packages\\matplotlib\\image.py\", line 131, in _draw_list_compositing_images\n",
      "    a.draw(renderer)\n",
      "  File \"C:\\Users\\16kat\\anaconda3\\lib\\site-packages\\matplotlib\\artist.py\", line 41, in draw_wrapper\n",
      "    return draw(artist, renderer, *args, **kwargs)\n",
      "  File \"C:\\Users\\16kat\\anaconda3\\lib\\site-packages\\matplotlib\\axis.py\", line 1169, in draw\n",
      "    tick.draw(renderer)\n",
      "  File \"C:\\Users\\16kat\\anaconda3\\lib\\site-packages\\matplotlib\\artist.py\", line 41, in draw_wrapper\n",
      "    return draw(artist, renderer, *args, **kwargs)\n",
      "  File \"C:\\Users\\16kat\\anaconda3\\lib\\site-packages\\matplotlib\\axis.py\", line 291, in draw\n",
      "    artist.draw(renderer)\n",
      "  File \"C:\\Users\\16kat\\anaconda3\\lib\\site-packages\\matplotlib\\artist.py\", line 41, in draw_wrapper\n",
      "    return draw(artist, renderer, *args, **kwargs)\n",
      "  File \"C:\\Users\\16kat\\anaconda3\\lib\\site-packages\\matplotlib\\text.py\", line 725, in draw\n",
      "    textrenderer.draw_text(gc, x, y, clean_line,\n",
      "  File \"C:\\Users\\16kat\\anaconda3\\lib\\site-packages\\matplotlib\\backends\\backend_agg.py\", line 195, in draw_text\n",
      "    font = self._get_agg_font(prop)\n",
      "  File \"C:\\Users\\16kat\\anaconda3\\lib\\site-packages\\matplotlib\\backends\\backend_agg.py\", line 272, in _get_agg_font\n",
      "    fname = findfont(prop)\n",
      "  File \"C:\\Users\\16kat\\anaconda3\\lib\\site-packages\\matplotlib\\font_manager.py\", line 1314, in findfont\n",
      "    return os.path.realpath(filename)\n",
      "  File \"C:\\Users\\16kat\\anaconda3\\lib\\ntpath.py\", line 647, in realpath\n",
      "    path = _getfinalpathname(path)\n",
      "KeyboardInterrupt\n",
      "\n",
      "During handling of the above exception, another exception occurred:\n",
      "\n",
      "Traceback (most recent call last):\n",
      "  File \"C:\\Users\\16kat\\anaconda3\\lib\\site-packages\\IPython\\core\\interactiveshell.py\", line 3418, in run_code\n",
      "    exec(code_obj, self.user_global_ns, self.user_ns)\n",
      "  File \"<ipython-input-6-4e619ad7cffb>\", line 1, in <module>\n",
      "    animate(train_data[0].reshape(n_time_steps,1, dim, dim), file_name = os.path.join(result_dir,'train_data.gif'))\n",
      "  File \"<ipython-input-5-2e1703cf0959>\", line 45, in animate\n",
      "    anim.save(file_name, writer=writergif)\n",
      "  File \"C:\\Users\\16kat\\anaconda3\\lib\\site-packages\\matplotlib\\animation.py\", line 1145, in save\n",
      "    writer.grab_frame(**savefig_kwargs)\n",
      "  File \"C:\\Users\\16kat\\anaconda3\\lib\\contextlib.py\", line 131, in __exit__\n",
      "    self.gen.throw(type, value, traceback)\n",
      "  File \"C:\\Users\\16kat\\anaconda3\\lib\\site-packages\\matplotlib\\animation.py\", line 253, in saving\n",
      "    self.finish()\n",
      "  File \"C:\\Users\\16kat\\anaconda3\\lib\\site-packages\\matplotlib\\animation.py\", line 554, in finish\n",
      "    self._frames[0].save(\n",
      "  File \"C:\\Users\\16kat\\anaconda3\\lib\\site-packages\\PIL\\Image.py\", line 2148, in save\n",
      "    fp = builtins.open(filename, \"w+b\")\n",
      "FileNotFoundError: [Errno 2] No such file or directory: './result/toy2a\\\\train_data.gif'\n",
      "\n",
      "During handling of the above exception, another exception occurred:\n",
      "\n",
      "Traceback (most recent call last):\n",
      "  File \"C:\\Users\\16kat\\anaconda3\\lib\\site-packages\\IPython\\core\\interactiveshell.py\", line 2045, in showtraceback\n",
      "    stb = value._render_traceback_()\n",
      "AttributeError: 'FileNotFoundError' object has no attribute '_render_traceback_'\n",
      "\n",
      "During handling of the above exception, another exception occurred:\n",
      "\n",
      "Traceback (most recent call last):\n",
      "  File \"C:\\Users\\16kat\\anaconda3\\lib\\site-packages\\IPython\\core\\interactiveshell.py\", line 3338, in run_ast_nodes\n",
      "    if (await self.run_code(code, result,  async_=asy)):\n",
      "  File \"C:\\Users\\16kat\\anaconda3\\lib\\site-packages\\IPython\\core\\interactiveshell.py\", line 3435, in run_code\n",
      "    self.showtraceback(running_compiled_code=True)\n",
      "  File \"C:\\Users\\16kat\\anaconda3\\lib\\site-packages\\IPython\\core\\interactiveshell.py\", line 2047, in showtraceback\n",
      "    stb = self.InteractiveTB.structured_traceback(etype,\n",
      "  File \"C:\\Users\\16kat\\anaconda3\\lib\\site-packages\\IPython\\core\\ultratb.py\", line 1436, in structured_traceback\n",
      "    return FormattedTB.structured_traceback(\n",
      "  File \"C:\\Users\\16kat\\anaconda3\\lib\\site-packages\\IPython\\core\\ultratb.py\", line 1336, in structured_traceback\n",
      "    return VerboseTB.structured_traceback(\n",
      "  File \"C:\\Users\\16kat\\anaconda3\\lib\\site-packages\\IPython\\core\\ultratb.py\", line 1193, in structured_traceback\n",
      "    formatted_exception = self.format_exception_as_a_whole(etype, evalue, etb, number_of_lines_of_context,\n",
      "  File \"C:\\Users\\16kat\\anaconda3\\lib\\site-packages\\IPython\\core\\ultratb.py\", line 1151, in format_exception_as_a_whole\n",
      "    last_unique, recursion_repeat = find_recursion(orig_etype, evalue, records)\n",
      "  File \"C:\\Users\\16kat\\anaconda3\\lib\\site-packages\\IPython\\core\\ultratb.py\", line 451, in find_recursion\n",
      "    return len(records), 0\n",
      "TypeError: object of type 'NoneType' has no len()\n",
      "\n",
      "During handling of the above exception, another exception occurred:\n",
      "\n",
      "Traceback (most recent call last):\n",
      "  File \"C:\\Users\\16kat\\anaconda3\\lib\\site-packages\\IPython\\core\\interactiveshell.py\", line 2045, in showtraceback\n",
      "    stb = value._render_traceback_()\n",
      "AttributeError: 'TypeError' object has no attribute '_render_traceback_'\n",
      "\n",
      "During handling of the above exception, another exception occurred:\n",
      "\n",
      "Traceback (most recent call last):\n",
      "  File \"C:\\Users\\16kat\\anaconda3\\lib\\site-packages\\IPython\\core\\interactiveshell.py\", line 2923, in _run_cell\n",
      "    return runner(coro)\n",
      "  File \"C:\\Users\\16kat\\anaconda3\\lib\\site-packages\\IPython\\core\\async_helpers.py\", line 68, in _pseudo_sync_runner\n",
      "    coro.send(None)\n",
      "  File \"C:\\Users\\16kat\\anaconda3\\lib\\site-packages\\IPython\\core\\interactiveshell.py\", line 3146, in run_cell_async\n",
      "    has_raised = await self.run_ast_nodes(code_ast.body, cell_name,\n",
      "  File \"C:\\Users\\16kat\\anaconda3\\lib\\site-packages\\IPython\\core\\interactiveshell.py\", line 3357, in run_ast_nodes\n",
      "    self.showtraceback()\n",
      "  File \"C:\\Users\\16kat\\anaconda3\\lib\\site-packages\\IPython\\core\\interactiveshell.py\", line 2047, in showtraceback\n",
      "    stb = self.InteractiveTB.structured_traceback(etype,\n",
      "  File \"C:\\Users\\16kat\\anaconda3\\lib\\site-packages\\IPython\\core\\ultratb.py\", line 1436, in structured_traceback\n",
      "    return FormattedTB.structured_traceback(\n",
      "  File \"C:\\Users\\16kat\\anaconda3\\lib\\site-packages\\IPython\\core\\ultratb.py\", line 1336, in structured_traceback\n",
      "    return VerboseTB.structured_traceback(\n",
      "  File \"C:\\Users\\16kat\\anaconda3\\lib\\site-packages\\IPython\\core\\ultratb.py\", line 1211, in structured_traceback\n",
      "    formatted_exceptions += self.format_exception_as_a_whole(etype, evalue, etb, lines_of_context,\n",
      "  File \"C:\\Users\\16kat\\anaconda3\\lib\\site-packages\\IPython\\core\\ultratb.py\", line 1151, in format_exception_as_a_whole\n",
      "    last_unique, recursion_repeat = find_recursion(orig_etype, evalue, records)\n",
      "  File \"C:\\Users\\16kat\\anaconda3\\lib\\site-packages\\IPython\\core\\ultratb.py\", line 451, in find_recursion\n",
      "    return len(records), 0\n",
      "TypeError: object of type 'NoneType' has no len()\n",
      "\n",
      "During handling of the above exception, another exception occurred:\n",
      "\n",
      "Traceback (most recent call last):\n",
      "  File \"C:\\Users\\16kat\\anaconda3\\lib\\site-packages\\IPython\\core\\interactiveshell.py\", line 2045, in showtraceback\n",
      "    stb = value._render_traceback_()\n",
      "AttributeError: 'TypeError' object has no attribute '_render_traceback_'\n",
      "\n",
      "During handling of the above exception, another exception occurred:\n",
      "\n",
      "Traceback (most recent call last):\n",
      "  File \"C:\\Users\\16kat\\anaconda3\\lib\\site-packages\\IPython\\core\\interactiveshell.py\", line 2877, in run_cell\n",
      "    result = self._run_cell(\n",
      "  File \"C:\\Users\\16kat\\anaconda3\\lib\\site-packages\\IPython\\core\\interactiveshell.py\", line 2928, in _run_cell\n",
      "    self.showtraceback(running_compiled_code=True)\n",
      "  File \"C:\\Users\\16kat\\anaconda3\\lib\\site-packages\\IPython\\core\\interactiveshell.py\", line 2047, in showtraceback\n",
      "    stb = self.InteractiveTB.structured_traceback(etype,\n",
      "  File \"C:\\Users\\16kat\\anaconda3\\lib\\site-packages\\IPython\\core\\ultratb.py\", line 1436, in structured_traceback\n",
      "    return FormattedTB.structured_traceback(\n",
      "  File \"C:\\Users\\16kat\\anaconda3\\lib\\site-packages\\IPython\\core\\ultratb.py\", line 1336, in structured_traceback\n",
      "    return VerboseTB.structured_traceback(\n",
      "  File \"C:\\Users\\16kat\\anaconda3\\lib\\site-packages\\IPython\\core\\ultratb.py\", line 1211, in structured_traceback\n",
      "    formatted_exceptions += self.format_exception_as_a_whole(etype, evalue, etb, lines_of_context,\n",
      "  File \"C:\\Users\\16kat\\anaconda3\\lib\\site-packages\\IPython\\core\\ultratb.py\", line 1151, in format_exception_as_a_whole\n",
      "    last_unique, recursion_repeat = find_recursion(orig_etype, evalue, records)\n",
      "  File \"C:\\Users\\16kat\\anaconda3\\lib\\site-packages\\IPython\\core\\ultratb.py\", line 451, in find_recursion\n",
      "    return len(records), 0\n",
      "TypeError: object of type 'NoneType' has no len()\n",
      "\n",
      "During handling of the above exception, another exception occurred:\n",
      "\n",
      "Traceback (most recent call last):\n",
      "  File \"C:\\Users\\16kat\\anaconda3\\lib\\site-packages\\IPython\\core\\events.py\", line 89, in trigger\n",
      "    func(*args, **kwargs)\n",
      "  File \"C:\\Users\\16kat\\anaconda3\\lib\\site-packages\\ipykernel\\pylab\\backend_inline.py\", line 121, in flush_figures\n",
      "    return show(True)\n",
      "  File \"C:\\Users\\16kat\\anaconda3\\lib\\site-packages\\ipykernel\\pylab\\backend_inline.py\", line 41, in show\n",
      "    display(\n",
      "  File \"C:\\Users\\16kat\\anaconda3\\lib\\site-packages\\IPython\\core\\display.py\", line 313, in display\n",
      "    format_dict, md_dict = format(obj, include=include, exclude=exclude)\n",
      "  File \"C:\\Users\\16kat\\anaconda3\\lib\\site-packages\\IPython\\core\\formatters.py\", line 180, in format\n",
      "    data = formatter(obj)\n",
      "  File \"<decorator-gen-2>\", line 2, in __call__\n",
      "  File \"C:\\Users\\16kat\\anaconda3\\lib\\site-packages\\IPython\\core\\formatters.py\", line 224, in catch_format_error\n",
      "    r = method(self, *args, **kwargs)\n",
      "  File \"C:\\Users\\16kat\\anaconda3\\lib\\site-packages\\IPython\\core\\formatters.py\", line 341, in __call__\n",
      "    return printer(obj)\n",
      "  File \"C:\\Users\\16kat\\anaconda3\\lib\\site-packages\\IPython\\core\\pylabtools.py\", line 248, in <lambda>\n",
      "    png_formatter.for_type(Figure, lambda fig: print_figure(fig, 'png', **kwargs))\n",
      "  File \"C:\\Users\\16kat\\anaconda3\\lib\\site-packages\\IPython\\core\\pylabtools.py\", line 132, in print_figure\n",
      "    fig.canvas.print_figure(bytes_io, **kw)\n",
      "  File \"C:\\Users\\16kat\\anaconda3\\lib\\site-packages\\matplotlib\\backend_bases.py\", line 2195, in print_figure\n",
      "    bbox_inches = self.figure.get_tightbbox(\n",
      "  File \"C:\\Users\\16kat\\anaconda3\\lib\\site-packages\\matplotlib\\figure.py\", line 2506, in get_tightbbox\n",
      "    bbox = a.get_tightbbox(renderer)\n",
      "  File \"C:\\Users\\16kat\\anaconda3\\lib\\site-packages\\matplotlib\\axes\\_base.py\", line 4155, in get_tightbbox\n",
      "    bb_xaxis = self.xaxis.get_tightbbox(\n",
      "  File \"C:\\Users\\16kat\\anaconda3\\lib\\site-packages\\matplotlib\\axis.py\", line 1111, in get_tightbbox\n",
      "    self._update_label_position(renderer)\n",
      "  File \"C:\\Users\\16kat\\anaconda3\\lib\\site-packages\\matplotlib\\axis.py\", line 2058, in _update_label_position\n",
      "    bboxes, bboxes2 = self._get_tick_boxes_siblings(renderer=renderer)\n",
      "  File \"C:\\Users\\16kat\\anaconda3\\lib\\site-packages\\matplotlib\\axis.py\", line 2042, in _get_tick_boxes_siblings\n",
      "    ticks_to_draw = axx.xaxis._update_ticks()\n",
      "  File \"C:\\Users\\16kat\\anaconda3\\lib\\site-packages\\matplotlib\\axis.py\", line 1022, in _update_ticks\n",
      "    major_labels = self.major.formatter.format_ticks(major_locs)\n",
      "  File \"C:\\Users\\16kat\\anaconda3\\lib\\site-packages\\matplotlib\\ticker.py\", line 249, in format_ticks\n",
      "    self.set_locs(values)\n",
      "  File \"C:\\Users\\16kat\\anaconda3\\lib\\site-packages\\matplotlib\\ticker.py\", line 780, in set_locs\n",
      "    self._compute_offset()\n",
      "  File \"C:\\Users\\16kat\\anaconda3\\lib\\site-packages\\matplotlib\\ticker.py\", line 793, in _compute_offset\n",
      "    lmin, lmax = locs.min(), locs.max()\n",
      "  File \"C:\\Users\\16kat\\anaconda3\\lib\\site-packages\\numpy\\core\\_methods.py\", line 43, in _amin\n",
      "    return umr_minimum(a, axis, None, out, keepdims, initial, where)\n",
      "KeyboardInterrupt\n",
      "\n",
      "During handling of the above exception, another exception occurred:\n",
      "\n",
      "Traceback (most recent call last):\n",
      "  File \"C:\\Users\\16kat\\anaconda3\\lib\\site-packages\\IPython\\core\\interactiveshell.py\", line 2045, in showtraceback\n",
      "    stb = value._render_traceback_()\n",
      "AttributeError: 'KeyboardInterrupt' object has no attribute '_render_traceback_'\n",
      "\n",
      "During handling of the above exception, another exception occurred:\n",
      "\n",
      "Traceback (most recent call last):\n",
      "  File \"C:\\Users\\16kat\\anaconda3\\lib\\site-packages\\IPython\\core\\ultratb.py\", line 1170, in get_records\n",
      "    return _fixed_getinnerframes(etb, number_of_lines_of_context, tb_offset)\n",
      "  File \"C:\\Users\\16kat\\anaconda3\\lib\\site-packages\\IPython\\core\\ultratb.py\", line 316, in wrapped\n",
      "    return f(*args, **kwargs)\n",
      "  File \"C:\\Users\\16kat\\anaconda3\\lib\\site-packages\\IPython\\core\\ultratb.py\", line 350, in _fixed_getinnerframes\n",
      "    records = fix_frame_records_filenames(inspect.getinnerframes(etb, context))\n",
      "  File \"C:\\Users\\16kat\\anaconda3\\lib\\inspect.py\", line 1503, in getinnerframes\n",
      "    frameinfo = (tb.tb_frame,) + getframeinfo(tb, context)\n",
      "  File \"C:\\Users\\16kat\\anaconda3\\lib\\inspect.py\", line 1461, in getframeinfo\n",
      "    filename = getsourcefile(frame) or getfile(frame)\n",
      "  File \"C:\\Users\\16kat\\anaconda3\\lib\\inspect.py\", line 708, in getsourcefile\n",
      "    if getattr(getmodule(object, filename), '__loader__', None) is not None:\n",
      "  File \"C:\\Users\\16kat\\anaconda3\\lib\\inspect.py\", line 754, in getmodule\n",
      "    os.path.realpath(f)] = module.__name__\n",
      "  File \"C:\\Users\\16kat\\anaconda3\\lib\\ntpath.py\", line 664, in realpath\n",
      "    if _getfinalpathname(spath) == path:\n",
      "KeyboardInterrupt\n"
     ]
    }
   ],
   "source": [
    "animate(train_data[0].reshape(n_time_steps,1, dim, dim), file_name = os.path.join(result_dir,'train_data.gif'))"
   ]
  },
  {
   "cell_type": "code",
   "execution_count": null,
   "metadata": {},
   "outputs": [],
   "source": []
  }
 ],
 "metadata": {
  "kernelspec": {
   "display_name": "Python 3 (ipykernel)",
   "language": "python",
   "name": "python3"
  },
  "language_info": {
   "codemirror_mode": {
    "name": "ipython",
    "version": 3
   },
   "file_extension": ".py",
   "mimetype": "text/x-python",
   "name": "python",
   "nbconvert_exporter": "python",
   "pygments_lexer": "ipython3",
   "version": "3.9.5"
  }
 },
 "nbformat": 4,
 "nbformat_minor": 4
}
